[2024-09-08T16:14:35.462+0000] {local_task_job_runner.py:123} INFO - ::group::Pre task execution logs
[2024-09-08T16:14:35.574+0000] {taskinstance.py:2612} INFO - Dependencies all met for dep_context=non-requeueable deps ti=<TaskInstance: exchange_rates_dag.run_main_script scheduled__2024-03-04T00:00:00+00:00 [queued]>
[2024-09-08T16:14:35.638+0000] {taskinstance.py:2612} INFO - Dependencies all met for dep_context=requeueable deps ti=<TaskInstance: exchange_rates_dag.run_main_script scheduled__2024-03-04T00:00:00+00:00 [queued]>
[2024-09-08T16:14:35.643+0000] {taskinstance.py:2865} INFO - Starting attempt 1 of 2
[2024-09-08T16:14:35.715+0000] {taskinstance.py:2888} INFO - Executing <Task(PythonOperator): run_main_script> on 2024-03-04 00:00:00+00:00
[2024-09-08T16:14:35.745+0000] {logging_mixin.py:190} WARNING - /home/***/.local/lib/python3.12/site-packages/***/task/task_runner/standard_task_runner.py:70 DeprecationWarning: This process (pid=302) is multi-threaded, use of fork() may lead to deadlocks in the child.
[2024-09-08T16:14:35.764+0000] {standard_task_runner.py:72} INFO - Started process 304 to run task
[2024-09-08T16:14:35.749+0000] {standard_task_runner.py:104} INFO - Running: ['***', 'tasks', 'run', 'exchange_rates_dag', 'run_main_script', 'scheduled__2024-03-04T00:00:00+00:00', '--job-id', '123', '--raw', '--subdir', 'DAGS_FOLDER/exchange_rates_dag.py', '--cfg-path', '/tmp/tmp9_nu8gih']
[2024-09-08T16:14:35.781+0000] {standard_task_runner.py:105} INFO - Job 123: Subtask run_main_script
[2024-09-08T16:14:36.010+0000] {task_command.py:467} INFO - Running <TaskInstance: exchange_rates_dag.run_main_script scheduled__2024-03-04T00:00:00+00:00 [running]> on host bd0133ae5e03
[2024-09-08T16:14:36.513+0000] {taskinstance.py:3131} INFO - Exporting env vars: AIRFLOW_CTX_DAG_OWNER='***' AIRFLOW_CTX_DAG_ID='exchange_rates_dag' AIRFLOW_CTX_TASK_ID='run_main_script' AIRFLOW_CTX_EXECUTION_DATE='2024-03-04T00:00:00+00:00' AIRFLOW_CTX_TRY_NUMBER='1' AIRFLOW_CTX_DAG_RUN_ID='scheduled__2024-03-04T00:00:00+00:00'
[2024-09-08T16:14:36.518+0000] {taskinstance.py:731} INFO - ::endgroup::
[2024-09-08T16:15:06.330+0000] {local_task_job_runner.py:127} ERROR - Received SIGTERM. Terminating subprocesses
[2024-09-08T16:15:06.588+0000] {process_utils.py:132} INFO - Sending 15 to group 304. PIDs of all processes in the group: [309, 304]
[2024-09-08T16:15:06.725+0000] {process_utils.py:87} INFO - Sending the signal 15 to group 304
[2024-09-08T16:15:06.826+0000] {taskinstance.py:3092} ERROR - Received SIGTERM. Terminating subprocesses.
[2024-09-08T16:15:08.037+0000] {taskinstance.py:3310} ERROR - Task failed with exception
Traceback (most recent call last):
  File "/home/airflow/.local/lib/python3.12/site-packages/airflow/models/taskinstance.py", line 767, in _execute_task
    result = _execute_callable(context=context, **execute_callable_kwargs)
             ^^^^^^^^^^^^^^^^^^^^^^^^^^^^^^^^^^^^^^^^^^^^^^^^^^^^^^^^^^^^^
  File "/home/airflow/.local/lib/python3.12/site-packages/airflow/models/taskinstance.py", line 733, in _execute_callable
    return ExecutionCallableRunner(
           ^^^^^^^^^^^^^^^^^^^^^^^^
  File "/home/airflow/.local/lib/python3.12/site-packages/airflow/utils/operator_helpers.py", line 252, in run
    return self.func(*args, **kwargs)
           ^^^^^^^^^^^^^^^^^^^^^^^^^^
  File "/home/airflow/.local/lib/python3.12/site-packages/airflow/models/baseoperator.py", line 406, in wrapper
    return func(self, *args, **kwargs)
           ^^^^^^^^^^^^^^^^^^^^^^^^^^^
  File "/home/airflow/.local/lib/python3.12/site-packages/airflow/operators/python.py", line 238, in execute
    return_value = self.execute_callable()
                   ^^^^^^^^^^^^^^^^^^^^^^^
  File "/home/airflow/.local/lib/python3.12/site-packages/airflow/operators/python.py", line 256, in execute_callable
    return runner.run(*self.op_args, **self.op_kwargs)
           ^^^^^^^^^^^^^^^^^^^^^^^^^^^^^^^^^^^^^^^^^^^
  File "/home/airflow/.local/lib/python3.12/site-packages/airflow/utils/operator_helpers.py", line 252, in run
    return self.func(*args, **kwargs)
           ^^^^^^^^^^^^^^^^^^^^^^^^^^
  File "/opt/airflow/dags/exchange_rates_dag.py", line 27, in run_main
    subprocess.run(["python3", "/opt/airflow/main.py"], check=True)
  File "/usr/local/lib/python3.12/subprocess.py", line 550, in run
    stdout, stderr = process.communicate(input, timeout=timeout)
                     ^^^^^^^^^^^^^^^^^^^^^^^^^^^^^^^^^^^^^^^^^^^
  File "/usr/local/lib/python3.12/subprocess.py", line 1201, in communicate
    self.wait()
  File "/usr/local/lib/python3.12/subprocess.py", line 1264, in wait
    return self._wait(timeout=timeout)
           ^^^^^^^^^^^^^^^^^^^^^^^^^^^
  File "/usr/local/lib/python3.12/subprocess.py", line 2053, in _wait
    (pid, sts) = self._try_wait(0)
                 ^^^^^^^^^^^^^^^^^
  File "/usr/local/lib/python3.12/subprocess.py", line 2011, in _try_wait
    (pid, sts) = os.waitpid(self.pid, wait_flags)
                 ^^^^^^^^^^^^^^^^^^^^^^^^^^^^^^^^
  File "/home/airflow/.local/lib/python3.12/site-packages/airflow/models/taskinstance.py", line 3094, in signal_handler
    raise AirflowTaskTerminated("Task received SIGTERM signal")
airflow.exceptions.AirflowTaskTerminated: Task received SIGTERM signal
[2024-09-08T16:15:08.559+0000] {process_utils.py:80} INFO - Process psutil.Process(pid=309, status='terminated', started='16:14:36') (309) terminated with exit code None
[2024-09-08T16:15:08.671+0000] {taskinstance.py:1225} INFO - Marking task as UP_FOR_RETRY. dag_id=exchange_rates_dag, task_id=run_main_script, run_id=scheduled__2024-03-04T00:00:00+00:00, execution_date=20240304T000000, start_date=20240908T161435, end_date=20240908T161508
[2024-09-08T16:15:10.428+0000] {taskinstance.py:340} INFO - ::group::Post task execution logs
[2024-09-08T16:15:10.624+0000] {process_utils.py:80} INFO - Process psutil.Process(pid=304, status='terminated', exitcode=2, started='16:14:35') (304) terminated with exit code 2
[2024-09-08T16:15:10.633+0000] {local_task_job_runner.py:266} INFO - Task exited with return code 143
[2024-09-08T16:15:10.797+0000] {standard_task_runner.py:217} INFO - Process not found (most likely exited), stop collecting metrics
[2024-09-08T16:15:10.922+0000] {taskinstance.py:3900} INFO - 0 downstream tasks scheduled from follow-on schedule check
[2024-09-08T16:15:10.971+0000] {local_task_job_runner.py:218} WARNING - Heartbeat failed with Exception: This Connection is closed
[2024-09-08T16:15:11.016+0000] {local_task_job_runner.py:245} INFO - ::endgroup::
[2024-09-15T05:54:12.454+0000] {local_task_job_runner.py:123} INFO - ::group::Pre task execution logs
[2024-09-15T05:54:12.668+0000] {taskinstance.py:2612} INFO - Dependencies all met for dep_context=non-requeueable deps ti=<TaskInstance: exchange_rates_dag.run_main_script scheduled__2024-03-04T00:00:00+00:00 [queued]>
[2024-09-15T05:54:12.821+0000] {taskinstance.py:2612} INFO - Dependencies all met for dep_context=requeueable deps ti=<TaskInstance: exchange_rates_dag.run_main_script scheduled__2024-03-04T00:00:00+00:00 [queued]>
[2024-09-15T05:54:12.833+0000] {taskinstance.py:2865} INFO - Starting attempt 1 of 2
[2024-09-15T05:54:13.719+0000] {taskinstance.py:2888} INFO - Executing <Task(PythonOperator): run_main_script> on 2024-03-04 00:00:00+00:00
[2024-09-15T05:54:13.804+0000] {logging_mixin.py:190} WARNING - /home/***/.local/lib/python3.12/site-packages/***/task/task_runner/standard_task_runner.py:70 DeprecationWarning: This process (pid=589) is multi-threaded, use of fork() may lead to deadlocks in the child.
[2024-09-15T05:54:13.822+0000] {standard_task_runner.py:72} INFO - Started process 595 to run task
[2024-09-15T05:54:13.800+0000] {standard_task_runner.py:104} INFO - Running: ['***', 'tasks', 'run', 'exchange_rates_dag', 'run_main_script', 'scheduled__2024-03-04T00:00:00+00:00', '--job-id', '179', '--raw', '--subdir', 'DAGS_FOLDER/exchange_rates_dag.py', '--cfg-path', '/tmp/tmp4_yumiag']
[2024-09-15T05:54:13.837+0000] {standard_task_runner.py:105} INFO - Job 179: Subtask run_main_script
[2024-09-15T05:54:14.368+0000] {task_command.py:467} INFO - Running <TaskInstance: exchange_rates_dag.run_main_script scheduled__2024-03-04T00:00:00+00:00 [running]> on host ed6b7035df5d
[2024-09-15T05:54:15.349+0000] {taskinstance.py:3131} INFO - Exporting env vars: AIRFLOW_CTX_DAG_EMAIL='***docker@gmail.com' AIRFLOW_CTX_DAG_OWNER='***' AIRFLOW_CTX_DAG_ID='exchange_rates_dag' AIRFLOW_CTX_TASK_ID='run_main_script' AIRFLOW_CTX_EXECUTION_DATE='2024-03-04T00:00:00+00:00' AIRFLOW_CTX_TRY_NUMBER='1' AIRFLOW_CTX_DAG_RUN_ID='scheduled__2024-03-04T00:00:00+00:00'
[2024-09-15T05:54:15.365+0000] {taskinstance.py:731} INFO - ::endgroup::
[2024-09-15T05:55:20.862+0000] {local_task_job_runner.py:127} ERROR - Received SIGTERM. Terminating subprocesses
[2024-09-15T05:55:21.118+0000] {process_utils.py:132} INFO - Sending 15 to group 595. PIDs of all processes in the group: [600, 595]
[2024-09-15T05:55:21.184+0000] {process_utils.py:87} INFO - Sending the signal 15 to group 595
[2024-09-15T05:55:21.221+0000] {taskinstance.py:3092} ERROR - Received SIGTERM. Terminating subprocesses.
[2024-09-15T05:55:21.899+0000] {process_utils.py:80} INFO - Process psutil.Process(pid=600, status='terminated', started='05:54:15') (600) terminated with exit code None
[2024-09-15T05:55:22.117+0000] {taskinstance.py:3310} ERROR - Task failed with exception
Traceback (most recent call last):
  File "/home/airflow/.local/lib/python3.12/site-packages/airflow/models/taskinstance.py", line 767, in _execute_task
    result = _execute_callable(context=context, **execute_callable_kwargs)
             ^^^^^^^^^^^^^^^^^^^^^^^^^^^^^^^^^^^^^^^^^^^^^^^^^^^^^^^^^^^^^
  File "/home/airflow/.local/lib/python3.12/site-packages/airflow/models/taskinstance.py", line 733, in _execute_callable
    return ExecutionCallableRunner(
           ^^^^^^^^^^^^^^^^^^^^^^^^
  File "/home/airflow/.local/lib/python3.12/site-packages/airflow/utils/operator_helpers.py", line 252, in run
    return self.func(*args, **kwargs)
           ^^^^^^^^^^^^^^^^^^^^^^^^^^
  File "/home/airflow/.local/lib/python3.12/site-packages/airflow/models/baseoperator.py", line 406, in wrapper
    return func(self, *args, **kwargs)
           ^^^^^^^^^^^^^^^^^^^^^^^^^^^
  File "/home/airflow/.local/lib/python3.12/site-packages/airflow/operators/python.py", line 238, in execute
    return_value = self.execute_callable()
                   ^^^^^^^^^^^^^^^^^^^^^^^
  File "/home/airflow/.local/lib/python3.12/site-packages/airflow/operators/python.py", line 256, in execute_callable
    return runner.run(*self.op_args, **self.op_kwargs)
           ^^^^^^^^^^^^^^^^^^^^^^^^^^^^^^^^^^^^^^^^^^^
  File "/home/airflow/.local/lib/python3.12/site-packages/airflow/utils/operator_helpers.py", line 252, in run
    return self.func(*args, **kwargs)
           ^^^^^^^^^^^^^^^^^^^^^^^^^^
  File "/opt/airflow/dags/exchange_rates_dag.py", line 29, in run_main
    subprocess.run(["python3", "/opt/airflow/main.py"], check=True)
  File "/usr/local/lib/python3.12/subprocess.py", line 550, in run
    stdout, stderr = process.communicate(input, timeout=timeout)
                     ^^^^^^^^^^^^^^^^^^^^^^^^^^^^^^^^^^^^^^^^^^^
  File "/usr/local/lib/python3.12/subprocess.py", line 1201, in communicate
    self.wait()
  File "/usr/local/lib/python3.12/subprocess.py", line 1264, in wait
    return self._wait(timeout=timeout)
           ^^^^^^^^^^^^^^^^^^^^^^^^^^^
  File "/usr/local/lib/python3.12/subprocess.py", line 2053, in _wait
    (pid, sts) = self._try_wait(0)
                 ^^^^^^^^^^^^^^^^^
  File "/usr/local/lib/python3.12/subprocess.py", line 2011, in _try_wait
    (pid, sts) = os.waitpid(self.pid, wait_flags)
                 ^^^^^^^^^^^^^^^^^^^^^^^^^^^^^^^^
  File "/home/airflow/.local/lib/python3.12/site-packages/airflow/models/taskinstance.py", line 3094, in signal_handler
    raise AirflowTaskTerminated("Task received SIGTERM signal")
airflow.exceptions.AirflowTaskTerminated: Task received SIGTERM signal
[2024-09-15T05:55:22.529+0000] {taskinstance.py:1225} INFO - Marking task as UP_FOR_RETRY. dag_id=exchange_rates_dag, task_id=run_main_script, run_id=scheduled__2024-03-04T00:00:00+00:00, execution_date=20240304T000000, start_date=20240915T055412, end_date=20240915T055522
[2024-09-15T05:55:23.269+0000] {taskinstance.py:340} INFO - ::group::Post task execution logs
[2024-09-15T05:55:23.576+0000] {process_utils.py:80} INFO - Process psutil.Process(pid=595, status='terminated', exitcode=2, started='05:54:13') (595) terminated with exit code 2
[2024-09-15T05:55:23.599+0000] {local_task_job_runner.py:266} INFO - Task exited with return code 143
[2024-09-15T05:55:23.900+0000] {standard_task_runner.py:217} INFO - Process not found (most likely exited), stop collecting metrics
[2024-09-15T05:55:24.648+0000] {taskinstance.py:3900} INFO - 0 downstream tasks scheduled from follow-on schedule check
[2024-09-15T05:55:24.955+0000] {local_task_job_runner.py:245} INFO - ::endgroup::
