[2024-09-08T16:14:36.049+0000] {local_task_job_runner.py:123} INFO - ::group::Pre task execution logs
[2024-09-08T16:14:36.145+0000] {taskinstance.py:2612} INFO - Dependencies all met for dep_context=non-requeueable deps ti=<TaskInstance: exchange_rates_dag.run_main_script scheduled__2024-03-05T00:00:00+00:00 [queued]>
[2024-09-08T16:14:36.196+0000] {taskinstance.py:2612} INFO - Dependencies all met for dep_context=requeueable deps ti=<TaskInstance: exchange_rates_dag.run_main_script scheduled__2024-03-05T00:00:00+00:00 [queued]>
[2024-09-08T16:14:36.201+0000] {taskinstance.py:2865} INFO - Starting attempt 1 of 2
[2024-09-08T16:14:36.356+0000] {taskinstance.py:2888} INFO - Executing <Task(PythonOperator): run_main_script> on 2024-03-05 00:00:00+00:00
[2024-09-08T16:14:36.395+0000] {logging_mixin.py:190} WARNING - /home/***/.local/lib/python3.12/site-packages/***/task/task_runner/standard_task_runner.py:70 DeprecationWarning: This process (pid=303) is multi-threaded, use of fork() may lead to deadlocks in the child.
[2024-09-08T16:14:36.401+0000] {standard_task_runner.py:72} INFO - Started process 307 to run task
[2024-09-08T16:14:36.390+0000] {standard_task_runner.py:104} INFO - Running: ['***', 'tasks', 'run', 'exchange_rates_dag', 'run_main_script', 'scheduled__2024-03-05T00:00:00+00:00', '--job-id', '124', '--raw', '--subdir', 'DAGS_FOLDER/exchange_rates_dag.py', '--cfg-path', '/tmp/tmprq6n9sey']
[2024-09-08T16:14:36.407+0000] {standard_task_runner.py:105} INFO - Job 124: Subtask run_main_script
[2024-09-08T16:14:36.593+0000] {task_command.py:467} INFO - Running <TaskInstance: exchange_rates_dag.run_main_script scheduled__2024-03-05T00:00:00+00:00 [running]> on host bd0133ae5e03
[2024-09-08T16:14:37.076+0000] {taskinstance.py:3131} INFO - Exporting env vars: AIRFLOW_CTX_DAG_OWNER='***' AIRFLOW_CTX_DAG_ID='exchange_rates_dag' AIRFLOW_CTX_TASK_ID='run_main_script' AIRFLOW_CTX_EXECUTION_DATE='2024-03-05T00:00:00+00:00' AIRFLOW_CTX_TRY_NUMBER='1' AIRFLOW_CTX_DAG_RUN_ID='scheduled__2024-03-05T00:00:00+00:00'
[2024-09-08T16:14:37.079+0000] {taskinstance.py:731} INFO - ::endgroup::
[2024-09-08T16:15:06.348+0000] {local_task_job_runner.py:127} ERROR - Received SIGTERM. Terminating subprocesses
[2024-09-08T16:15:06.555+0000] {process_utils.py:132} INFO - Sending 15 to group 307. PIDs of all processes in the group: [312, 307]
[2024-09-08T16:15:06.712+0000] {process_utils.py:87} INFO - Sending the signal 15 to group 307
[2024-09-08T16:15:06.764+0000] {taskinstance.py:3092} ERROR - Received SIGTERM. Terminating subprocesses.
[2024-09-08T16:15:07.777+0000] {process_utils.py:80} INFO - Process psutil.Process(pid=312, status='terminated', started='16:14:36') (312) terminated with exit code None
[2024-09-08T16:15:07.833+0000] {taskinstance.py:3310} ERROR - Task failed with exception
Traceback (most recent call last):
  File "/home/airflow/.local/lib/python3.12/site-packages/airflow/models/taskinstance.py", line 767, in _execute_task
    result = _execute_callable(context=context, **execute_callable_kwargs)
             ^^^^^^^^^^^^^^^^^^^^^^^^^^^^^^^^^^^^^^^^^^^^^^^^^^^^^^^^^^^^^
  File "/home/airflow/.local/lib/python3.12/site-packages/airflow/models/taskinstance.py", line 733, in _execute_callable
    return ExecutionCallableRunner(
           ^^^^^^^^^^^^^^^^^^^^^^^^
  File "/home/airflow/.local/lib/python3.12/site-packages/airflow/utils/operator_helpers.py", line 252, in run
    return self.func(*args, **kwargs)
           ^^^^^^^^^^^^^^^^^^^^^^^^^^
  File "/home/airflow/.local/lib/python3.12/site-packages/airflow/models/baseoperator.py", line 406, in wrapper
    return func(self, *args, **kwargs)
           ^^^^^^^^^^^^^^^^^^^^^^^^^^^
  File "/home/airflow/.local/lib/python3.12/site-packages/airflow/operators/python.py", line 238, in execute
    return_value = self.execute_callable()
                   ^^^^^^^^^^^^^^^^^^^^^^^
  File "/home/airflow/.local/lib/python3.12/site-packages/airflow/operators/python.py", line 256, in execute_callable
    return runner.run(*self.op_args, **self.op_kwargs)
           ^^^^^^^^^^^^^^^^^^^^^^^^^^^^^^^^^^^^^^^^^^^
  File "/home/airflow/.local/lib/python3.12/site-packages/airflow/utils/operator_helpers.py", line 252, in run
    return self.func(*args, **kwargs)
           ^^^^^^^^^^^^^^^^^^^^^^^^^^
  File "/opt/airflow/dags/exchange_rates_dag.py", line 27, in run_main
    subprocess.run(["python3", "/opt/airflow/main.py"], check=True)
  File "/usr/local/lib/python3.12/subprocess.py", line 550, in run
    stdout, stderr = process.communicate(input, timeout=timeout)
                     ^^^^^^^^^^^^^^^^^^^^^^^^^^^^^^^^^^^^^^^^^^^
  File "/usr/local/lib/python3.12/subprocess.py", line 1201, in communicate
    self.wait()
  File "/usr/local/lib/python3.12/subprocess.py", line 1264, in wait
    return self._wait(timeout=timeout)
           ^^^^^^^^^^^^^^^^^^^^^^^^^^^
  File "/usr/local/lib/python3.12/subprocess.py", line 2053, in _wait
    (pid, sts) = self._try_wait(0)
                 ^^^^^^^^^^^^^^^^^
  File "/usr/local/lib/python3.12/subprocess.py", line 2011, in _try_wait
    (pid, sts) = os.waitpid(self.pid, wait_flags)
                 ^^^^^^^^^^^^^^^^^^^^^^^^^^^^^^^^
  File "/home/airflow/.local/lib/python3.12/site-packages/airflow/models/taskinstance.py", line 3094, in signal_handler
    raise AirflowTaskTerminated("Task received SIGTERM signal")
airflow.exceptions.AirflowTaskTerminated: Task received SIGTERM signal
[2024-09-08T16:15:08.451+0000] {taskinstance.py:1225} INFO - Marking task as UP_FOR_RETRY. dag_id=exchange_rates_dag, task_id=run_main_script, run_id=scheduled__2024-03-05T00:00:00+00:00, execution_date=20240305T000000, start_date=20240908T161436, end_date=20240908T161508
[2024-09-08T16:15:10.445+0000] {taskinstance.py:340} INFO - ::group::Post task execution logs
[2024-09-08T16:15:10.657+0000] {process_utils.py:80} INFO - Process psutil.Process(pid=307, status='terminated', exitcode=2, started='16:14:36') (307) terminated with exit code 2
[2024-09-08T16:15:10.673+0000] {local_task_job_runner.py:266} INFO - Task exited with return code 143
[2024-09-08T16:15:10.955+0000] {taskinstance.py:3900} INFO - 0 downstream tasks scheduled from follow-on schedule check
[2024-09-08T16:15:11.277+0000] {local_task_job_runner.py:245} INFO - ::endgroup::
[2024-09-08T16:15:11.489+0000] {standard_task_runner.py:217} INFO - Process not found (most likely exited), stop collecting metrics
[2024-09-15T05:54:14.031+0000] {local_task_job_runner.py:123} INFO - ::group::Pre task execution logs
[2024-09-15T05:54:14.243+0000] {taskinstance.py:2612} INFO - Dependencies all met for dep_context=non-requeueable deps ti=<TaskInstance: exchange_rates_dag.run_main_script scheduled__2024-03-05T00:00:00+00:00 [queued]>
[2024-09-15T05:54:14.394+0000] {taskinstance.py:2612} INFO - Dependencies all met for dep_context=requeueable deps ti=<TaskInstance: exchange_rates_dag.run_main_script scheduled__2024-03-05T00:00:00+00:00 [queued]>
[2024-09-15T05:54:14.409+0000] {taskinstance.py:2865} INFO - Starting attempt 1 of 2
[2024-09-15T05:54:15.529+0000] {taskinstance.py:2888} INFO - Executing <Task(PythonOperator): run_main_script> on 2024-03-05 00:00:00+00:00
[2024-09-15T05:54:15.608+0000] {logging_mixin.py:190} WARNING - /home/***/.local/lib/python3.12/site-packages/***/task/task_runner/standard_task_runner.py:70 DeprecationWarning: This process (pid=593) is multi-threaded, use of fork() may lead to deadlocks in the child.
[2024-09-15T05:54:15.634+0000] {standard_task_runner.py:72} INFO - Started process 599 to run task
[2024-09-15T05:54:15.617+0000] {standard_task_runner.py:104} INFO - Running: ['***', 'tasks', 'run', 'exchange_rates_dag', 'run_main_script', 'scheduled__2024-03-05T00:00:00+00:00', '--job-id', '180', '--raw', '--subdir', 'DAGS_FOLDER/exchange_rates_dag.py', '--cfg-path', '/tmp/tmpx9i3_yro']
[2024-09-15T05:54:15.651+0000] {standard_task_runner.py:105} INFO - Job 180: Subtask run_main_script
[2024-09-15T05:54:16.399+0000] {task_command.py:467} INFO - Running <TaskInstance: exchange_rates_dag.run_main_script scheduled__2024-03-05T00:00:00+00:00 [running]> on host ed6b7035df5d
[2024-09-15T05:54:17.614+0000] {taskinstance.py:3131} INFO - Exporting env vars: AIRFLOW_CTX_DAG_EMAIL='***docker@gmail.com' AIRFLOW_CTX_DAG_OWNER='***' AIRFLOW_CTX_DAG_ID='exchange_rates_dag' AIRFLOW_CTX_TASK_ID='run_main_script' AIRFLOW_CTX_EXECUTION_DATE='2024-03-05T00:00:00+00:00' AIRFLOW_CTX_TRY_NUMBER='1' AIRFLOW_CTX_DAG_RUN_ID='scheduled__2024-03-05T00:00:00+00:00'
[2024-09-15T05:54:17.630+0000] {taskinstance.py:731} INFO - ::endgroup::
[2024-09-15T05:55:20.795+0000] {local_task_job_runner.py:127} ERROR - Received SIGTERM. Terminating subprocesses
[2024-09-15T05:55:21.112+0000] {process_utils.py:132} INFO - Sending 15 to group 599. PIDs of all processes in the group: [604, 599]
[2024-09-15T05:55:21.170+0000] {process_utils.py:87} INFO - Sending the signal 15 to group 599
[2024-09-15T05:55:21.234+0000] {taskinstance.py:3092} ERROR - Received SIGTERM. Terminating subprocesses.
[2024-09-15T05:55:21.728+0000] {process_utils.py:80} INFO - Process psutil.Process(pid=604, status='terminated', started='05:54:17') (604) terminated with exit code None
[2024-09-15T05:55:22.053+0000] {taskinstance.py:3310} ERROR - Task failed with exception
Traceback (most recent call last):
  File "/home/airflow/.local/lib/python3.12/site-packages/airflow/models/taskinstance.py", line 767, in _execute_task
    result = _execute_callable(context=context, **execute_callable_kwargs)
             ^^^^^^^^^^^^^^^^^^^^^^^^^^^^^^^^^^^^^^^^^^^^^^^^^^^^^^^^^^^^^
  File "/home/airflow/.local/lib/python3.12/site-packages/airflow/models/taskinstance.py", line 733, in _execute_callable
    return ExecutionCallableRunner(
           ^^^^^^^^^^^^^^^^^^^^^^^^
  File "/home/airflow/.local/lib/python3.12/site-packages/airflow/utils/operator_helpers.py", line 252, in run
    return self.func(*args, **kwargs)
           ^^^^^^^^^^^^^^^^^^^^^^^^^^
  File "/home/airflow/.local/lib/python3.12/site-packages/airflow/models/baseoperator.py", line 406, in wrapper
    return func(self, *args, **kwargs)
           ^^^^^^^^^^^^^^^^^^^^^^^^^^^
  File "/home/airflow/.local/lib/python3.12/site-packages/airflow/operators/python.py", line 238, in execute
    return_value = self.execute_callable()
                   ^^^^^^^^^^^^^^^^^^^^^^^
  File "/home/airflow/.local/lib/python3.12/site-packages/airflow/operators/python.py", line 256, in execute_callable
    return runner.run(*self.op_args, **self.op_kwargs)
           ^^^^^^^^^^^^^^^^^^^^^^^^^^^^^^^^^^^^^^^^^^^
  File "/home/airflow/.local/lib/python3.12/site-packages/airflow/utils/operator_helpers.py", line 252, in run
    return self.func(*args, **kwargs)
           ^^^^^^^^^^^^^^^^^^^^^^^^^^
  File "/opt/airflow/dags/exchange_rates_dag.py", line 29, in run_main
    subprocess.run(["python3", "/opt/airflow/main.py"], check=True)
  File "/usr/local/lib/python3.12/subprocess.py", line 550, in run
    stdout, stderr = process.communicate(input, timeout=timeout)
                     ^^^^^^^^^^^^^^^^^^^^^^^^^^^^^^^^^^^^^^^^^^^
  File "/usr/local/lib/python3.12/subprocess.py", line 1201, in communicate
    self.wait()
  File "/usr/local/lib/python3.12/subprocess.py", line 1264, in wait
    return self._wait(timeout=timeout)
           ^^^^^^^^^^^^^^^^^^^^^^^^^^^
  File "/usr/local/lib/python3.12/subprocess.py", line 2053, in _wait
    (pid, sts) = self._try_wait(0)
                 ^^^^^^^^^^^^^^^^^
  File "/usr/local/lib/python3.12/subprocess.py", line 2011, in _try_wait
    (pid, sts) = os.waitpid(self.pid, wait_flags)
                 ^^^^^^^^^^^^^^^^^^^^^^^^^^^^^^^^
  File "/home/airflow/.local/lib/python3.12/site-packages/airflow/models/taskinstance.py", line 3094, in signal_handler
    raise AirflowTaskTerminated("Task received SIGTERM signal")
airflow.exceptions.AirflowTaskTerminated: Task received SIGTERM signal
[2024-09-15T05:55:22.498+0000] {taskinstance.py:1225} INFO - Marking task as UP_FOR_RETRY. dag_id=exchange_rates_dag, task_id=run_main_script, run_id=scheduled__2024-03-05T00:00:00+00:00, execution_date=20240305T000000, start_date=20240915T055414, end_date=20240915T055522
[2024-09-15T05:55:23.074+0000] {taskinstance.py:340} INFO - ::group::Post task execution logs
[2024-09-15T05:55:23.359+0000] {process_utils.py:80} INFO - Process psutil.Process(pid=599, status='terminated', exitcode=2, started='05:54:15') (599) terminated with exit code 2
[2024-09-15T05:55:23.376+0000] {local_task_job_runner.py:266} INFO - Task exited with return code 143
[2024-09-15T05:55:24.356+0000] {taskinstance.py:3900} INFO - 0 downstream tasks scheduled from follow-on schedule check
[2024-09-15T05:55:24.624+0000] {local_task_job_runner.py:245} INFO - ::endgroup::
